2024-02-21 23:43:17,986 - instabot version: 0.117.0 (bot) - INFO - Instabot version: 0.117.0 Started
2024-02-21 23:43:17,987 - instabot version: 0.117.0 (bot) - DEBUG - Bot imported from C:\Users\deepi\AppData\Local\Programs\Python\Python311\Lib\site-packages\instabot\bot\bot.py
2024-02-21 23:43:17,987 - instabot version: 0.117.0 (api_login) - INFO - Not yet logged in starting: PRE-LOGIN FLOW!
2024-02-21 23:43:17,994 - instabot version: 0.117.0 (api) - WARNING - HTTPSConnectionPool(host='i.instagram.com', port=443): Max retries exceeded with url: /api/v1/accounts/get_prefill_candidates/ (Caused by NameResolutionError("<urllib3.connection.HTTPSConnection object at 0x000001C18E7A97D0>: Failed to resolve 'i.instagram.com' ([Errno 11001] getaddrinfo failed)"))
2024-02-21 23:43:17,997 - instabot version: 0.117.0 (api) - WARNING - HTTPSConnectionPool(host='i.instagram.com', port=443): Max retries exceeded with url: /api/v1/qe/sync/ (Caused by NameResolutionError("<urllib3.connection.HTTPSConnection object at 0x000001C18E7A8710>: Failed to resolve 'i.instagram.com' ([Errno 11001] getaddrinfo failed)"))
2024-02-21 23:43:17,999 - instabot version: 0.117.0 (api) - WARNING - HTTPSConnectionPool(host='i.instagram.com', port=443): Max retries exceeded with url: /api/v1/launcher/sync/ (Caused by NameResolutionError("<urllib3.connection.HTTPSConnection object at 0x000001C18E7B44D0>: Failed to resolve 'i.instagram.com' ([Errno 11001] getaddrinfo failed)"))
2024-02-21 23:43:18,001 - instabot version: 0.117.0 (api) - WARNING - HTTPSConnectionPool(host='i.instagram.com', port=443): Max retries exceeded with url: /api/v1/accounts/contact_point_prefill/ (Caused by NameResolutionError("<urllib3.connection.HTTPSConnection object at 0x000001C18E7B68D0>: Failed to resolve 'i.instagram.com' ([Errno 11001] getaddrinfo failed)"))
