2024-01-06 21:08:51,283 - instabot version: 0.117.0 (bot) - INFO - Instabot version: 0.117.0 Started
2024-01-06 21:08:51,284 - instabot version: 0.117.0 (bot) - DEBUG - Bot imported from C:\Users\deepi\AppData\Local\Programs\Python\Python311\Lib\site-packages\instabot\bot\bot.py
2024-01-06 21:08:51,284 - instabot version: 0.117.0 (api_login) - INFO - Not yet logged in starting: PRE-LOGIN FLOW!
2024-01-06 21:09:03,351 - instabot version: 0.117.0 (api) - WARNING - HTTPSConnectionPool(host='i.instagram.com', port=443): Max retries exceeded with url: /api/v1/accounts/get_prefill_candidates/ (Caused by NameResolutionError("<urllib3.connection.HTTPSConnection object at 0x000001B4DB119A90>: Failed to resolve 'i.instagram.com' ([Errno 11001] getaddrinfo failed)"))
2024-01-06 21:09:03,358 - instabot version: 0.117.0 (api) - WARNING - HTTPSConnectionPool(host='i.instagram.com', port=443): Max retries exceeded with url: /api/v1/qe/sync/ (Caused by NameResolutionError("<urllib3.connection.HTTPSConnection object at 0x000001B4DB431C90>: Failed to resolve 'i.instagram.com' ([Errno 11001] getaddrinfo failed)"))
2024-01-06 21:09:03,363 - instabot version: 0.117.0 (api) - WARNING - HTTPSConnectionPool(host='i.instagram.com', port=443): Max retries exceeded with url: /api/v1/launcher/sync/ (Caused by NameResolutionError("<urllib3.connection.HTTPSConnection object at 0x000001B4DB433990>: Failed to resolve 'i.instagram.com' ([Errno 11001] getaddrinfo failed)"))
2024-01-06 21:09:03,368 - instabot version: 0.117.0 (api) - WARNING - HTTPSConnectionPool(host='i.instagram.com', port=443): Max retries exceeded with url: /api/v1/accounts/contact_point_prefill/ (Caused by NameResolutionError("<urllib3.connection.HTTPSConnection object at 0x000001B4DB441E10>: Failed to resolve 'i.instagram.com' ([Errno 11001] getaddrinfo failed)"))
