2024-03-18 09:20:01,589 - instabot version: 0.117.0 (bot) - INFO - Instabot version: 0.117.0 Started
2024-03-18 09:20:01,591 - instabot version: 0.117.0 (bot) - DEBUG - Bot imported from C:\Users\deepi\AppData\Local\Programs\Python\Python311\Lib\site-packages\instabot\bot\bot.py
2024-03-18 09:20:01,593 - instabot version: 0.117.0 (api_login) - INFO - Not yet logged in starting: PRE-LOGIN FLOW!
2024-03-18 09:20:01,612 - instabot version: 0.117.0 (api) - WARNING - HTTPSConnectionPool(host='i.instagram.com', port=443): Max retries exceeded with url: /api/v1/accounts/get_prefill_candidates/ (Caused by NameResolutionError("<urllib3.connection.HTTPSConnection object at 0x000001E64A679710>: Failed to resolve 'i.instagram.com' ([Errno 11001] getaddrinfo failed)"))
2024-03-18 09:20:01,637 - instabot version: 0.117.0 (api) - WARNING - HTTPSConnectionPool(host='i.instagram.com', port=443): Max retries exceeded with url: /api/v1/qe/sync/ (Caused by NameResolutionError("<urllib3.connection.HTTPSConnection object at 0x000001E64A678650>: Failed to resolve 'i.instagram.com' ([Errno 11001] getaddrinfo failed)"))
2024-03-18 09:20:01,642 - instabot version: 0.117.0 (api) - WARNING - HTTPSConnectionPool(host='i.instagram.com', port=443): Max retries exceeded with url: /api/v1/launcher/sync/ (Caused by NameResolutionError("<urllib3.connection.HTTPSConnection object at 0x000001E64A6843D0>: Failed to resolve 'i.instagram.com' ([Errno 11001] getaddrinfo failed)"))
2024-03-18 09:20:01,646 - instabot version: 0.117.0 (api) - WARNING - HTTPSConnectionPool(host='i.instagram.com', port=443): Max retries exceeded with url: /api/v1/accounts/contact_point_prefill/ (Caused by NameResolutionError("<urllib3.connection.HTTPSConnection object at 0x000001E64A686810>: Failed to resolve 'i.instagram.com' ([Errno 11001] getaddrinfo failed)"))
